Workbook
Name Slicer_Date: #N/A
Name Slicer_Region: #N/A

Sheet Dashboard
A1: Performance Summary

Sheet Business_Analysis
A1: KPIs (Key Performance Indicators)
A2: 1. Total Net Sales | B2: 2. Total Profit | C2: 3. Overall Profit Margin | E2: 4. Count of loss-making Orders | H2: 5. Total loss from loss-making orders | K2: Delhi's Laptop Sales
A3: =SUM(Cleaned_Sales_data[Net_Sales]) -> 27886745 | B3: =SUM(Cleaned_Sales_data[Profit]) -> 2395103 | C3: =B3/A3 -> 0.08588679 | E3: =COUNTIFS('Cleaned_Sales_Data (Part A & B)'!Q2:Q751, "<0") -> 177 | H3: =SUMIFS('Cleaned_Sales_Data (Part A & B)'!Q2:Q751, 'Cleaned_Sales_Data (Part A & B)'!Q2:Q751, "<0") -> -240438 | K3: =SUMIFS('Cleaned_Sales_Data (Part A & B)'!L2:L751,'Cleaned_Sales_Data (Part A & B)'!E2:E751, "Delhi", 'Cleaned_Sales_Data (Part A & B)'!C2:C751,"Laptop") -> 1933750
A5: 6. Avg. Order Value | C5: 7. Highest Order Value | E5: Product with highest revenue | H5: Region with highest profit | J5: Region with lowest profit margin
A6: =A3/COUNTIF(Cleaned_Sales_data[Order_ID],"<>") -> 37182.327 | C6: =MAX('Cleaned_Sales_Data (Part A & B)'!L2:L751) -> 195000 | E6: Laptop | H6: Chennai | J6: Hyderabad
A8: Corporate Loss Orders (Count)
A9: =COUNTIFS('Cleaned_Sales_Data (Part A & B)'!F2:F751, "Corporate", 'Cleaned_Sales_Data (Part A & B)'!Q2:Q751,"<0") -> 38
A11: Region With Profit Margin | F11: Profit and Sales By Product
A12: Region | B12: Net Sales | C12: Net Profit | D12: Profit margin | F12: Product | G12: Net Sales | H12: Net Profit | J12: Total Sales By Channel
A13: Chennai | B13: 5808410 | C13: 490560 | D13: 0.084456848 | F13: Laptop | G13: 10512450 | H13: 728705 | J13: Channel | K13: Net Sales
A14: Mumbai | B14: 4716460 | C14: 413536 | D14: 0.087679319 | F14: Tablet | G14: 5830720 | H14: 494094 | J14: Online | K14: 13564080
A15: Bangalore | B15: 4645485 | C15: 424492 | D15: 0.091377327 | F15: Monitor | G15: 4068680 | H15: 435595 | J15: Retail | K15: 8959570
A16: Delhi | B16: 4535600 | C16: 386782 | D16: 0.08527692 | F16: Webcam | G16: 1742895 | H16: 279418 | J16: Corporate | K16: 5363095
A17: Pune | B17: 4203480 | C17: 384461 | D17: 0.09146255 | F17: Printer | G17: 3158820 | H17: 261992 | J17: Grand Total | K17: 27886745
A18: Hyderabad | B18: 3977310 | C18: 295272 | D18: 0.074239121 | F18: Keyboard | G18: 964975 | H18: 103585
A19: Grand Total | B19: 27886745 | C19: 2395103 | D19: 0.08588679 | F19: Headphones | G19: 1037575 | H19: 99896 | J19: Avg Order Value and Sales By Customer Type
F20: Mouse | G20: 570630 | H20: -8182 | J20: Customer_Type | K20: Net Sales | L20: Average order Value
F21: Grand Total | G21: 27886745 | H21: 2395103 | J21: New | K21: 13300705 | L21: 38441.344
J22: Returning | K22: 10423455 | L22: 34978.037
J23: Enterprise | K23: 4162585 | L23: 39269.67
J24: Grand Total | K24: 27886745 | L24: 37182.327
A25: Region and product wise net sales
A26: Net_sales | B26: Region
A27: Products | B27: Bangalore | C27: Chennai | D27: Delhi | E27: Hyderabad | F27: Mumbai | G27: Pune | H27: Grand Total
A28: Headphones | B28: 175805 | C28: 155960 | D28: 124075 | E28: 210630 | F28: 203420 | G28: 167685 | H28: 1037575
A29: Keyboard | B29: 188075 | C29: 123075 | D29: 166600 | E29: 185750 | F29: 139175 | G29: 162300 | H29: 964975
A30: Laptop | B30: 1825850 | C30: 2397850 | D30: 1933750 | E30: 1145950 | F30: 2029300 | G30: 1179750 | H30: 10512450
A31: Monitor | B31: 434840 | C31: 1009120 | D31: 473480 | E31: 744240 | F31: 731360 | G31: 675640 | H31: 4068680
A32: Mouse | B32: 87045 | C32: 84360 | D32: 108165 | E32: 59340 | F32: 86805 | G32: 144915 | H32: 570630
A33: Printer | B33: 629820 | C33: 541620 | D33: 505800 | E33: 604980 | F33: 417060 | G33: 459540 | H33: 3158820
A34: Tablet | B34: 999040 | C34: 1240960 | D34: 866880 | E34: 772800 | F34: 826560 | G34: 1124480 | H34: 5830720
A35: Webcam | B35: 305010 | C35: 255465 | D35: 356850 | E35: 253620 | F35: 282780 | G35: 289170 | H35: 1742895
A36: Grand Total | B36: 4645485 | C36: 5808410 | D36: 4535600 | E36: 3977310 | F36: 4716460 | G36: 4203480 | H36: 27886745
A39: Region And channel wise Net sales | G39: Revenue and profit by year and month
A40: Net_sales | B40: Channel | H40: Year
A41: Region | B41: Corporate | C41: Online | D41: Retail | E41: Grand Total | H41: 2025 | J41: 2026 | L41: Total Net_sales | M41: Total Profit
A42: Bangalore | B42: 1076580 | C42: 1976740 | D42: 1592165 | E42: 4645485 | G42: Month | H42: Net_sales | I42: Profit | J42: Net_sales | K42: Profit
A43: Chennai | B43: 893525 | C43: 2698235 | D43: 2216650 | E43: 5808410 | G43: Jan | H43: 950465 | I43: 59150 | J43: 1721690 | K43: 129683 | L43: 2672155 | M43: 188833
A44: Delhi | B44: 1094120 | C44: 2278800 | D44: 1162680 | E44: 4535600 | G44: Feb | H44: 1223865 | I44: 112548 | J44: 1277860 | K44: 156964 | L44: 2501725 | M44: 269512
A45: Hyderabad | B45: 500345 | C45: 1966675 | D45: 1510290 | E45: 3977310 | G45: Mar | H45: 1584070 | I45: 106271 | J45: 1720715 | K45: 123686 | L45: 3304785 | M45: 229957
...

Sheet Cleaned_Sales_Data (Part A & B)
A1: Order_ID | B1: Date | C1: Product | D1: Category | E1: Region | F1: Channel | G1: Customer_Type | H1: Quantity | I1: Unit_Price | J1: Discount | K1: Gross_Sales | L1: Net_Sales | M1: Product_Cost | N1: Shipping_Cost | O1: Marketing_Cost | P1: Standard Cost | Q1: Profit | R1: Profit_Margin | S1: Target_Margin | T1: Profit Status | U1: Profit Level | V1: Margin_status | W1: Month
A2: ORD-00008 | B2: 45927 | C2: Tablet | D2: =INDEX(Raw_product_master[Category],MATCH(Cleaned_Sales_data[[#This Row],[Product]],Raw_product_master[Product],0)) -> Computers | E2: Chennai | F2: Online | G2: New | H2: 2 | I2: 32000 | J2: 0.1 | K2: 64000 | L2: 57600 | M2: 52480 | N2: 361 | O2: 301 | P2: =INDEX(Raw_product_master[Standard_Cost_Per_Unit],MATCH(Cleaned_Sales_data[[#This Row],[Product]],Raw_product_master[Product],0)) -> 26240 | Q2: 4458 | R2: 0.077395833 | S2: =INDEX(Raw_product_master[Target_Margin], MATCH(Cleaned_Sales_data[[#This Row],[Product]],Raw_product_master[Product], 0 )) -> 0.12 | T2: =IF(Cleaned_Sales_data[[#This Row],[Profit]]>0, "Profitable", "Loss") -> Profitable | U2: =_xlfn.IFS(Cleaned_Sales_data[[#This Row],[Profit]]>=10000, "High", Cleaned_Sales_data[[#This Row],[Profit]]>=5000, "Medium", Cleaned_Sales_data[[#This Row],[Profit]]>=0, "Low", Cleaned_Sales_data[[#This Row],[Profit]] <0, "Loss") -> Low | V2: =IF(R2<S2, "UnderPerforming", "On Target") -> UnderPerforming | W2: 45901
A3: ORD-00010 | B3: 45786 | C3: Headphones | D3: =INDEX(Raw_product_master[Category],MATCH(Cleaned_Sales_data[[#This Row],[Product]],Raw_product_master[Product],0)) -> Accessories | E3: Hyderabad | F3: Online | G3: New | H3: 1 | I3: 3500 | J3: 0.05 | K3: 3500 | L3: 3325 | M3: 2380 | N3: 264 | O3: 1467 | P3: =INDEX(Raw_product_master[Standard_Cost_Per_Unit],MATCH(Cleaned_Sales_data[[#This Row],[Product]],Raw_product_master[Product],0)) -> 2380 | Q3: -786 | R3: -0.23639098 | S3: =INDEX(Raw_product_master[Target_Margin], MATCH(Cleaned_Sales_data[[#This Row],[Product]],Raw_product_master[Product], 0 )) -> 0.2 | T3: =IF(Cleaned_Sales_data[[#This Row],[Profit]]>0, "Profitable", "Loss") -> Loss | U3: =_xlfn.IFS(Cleaned_Sales_data[[#This Row],[Profit]]>=10000, "High", Cleaned_Sales_data[[#This Row],[Profit]]>=5000, "Medium", Cleaned_Sales_data[[#This Row],[Profit]]>=0, "Low", Cleaned_Sales_data[[#This Row],[Profit]] <0, "Loss") -> Loss | V3: =IF(R3<S3, "UnderPerforming", "On Target") -> UnderPerforming | W3: 45778
A4: ORD-00013 | B4: 45662 | C4: Printer | D4: =INDEX(Raw_product_master[Category],MATCH(Cleaned_Sales_data[[#This Row],[Product]],Raw_product_master[Product],0)) -> Office Equipment | E4: Mumbai | F4: Online | G4: New | H4: 2 | I4: 18000 | J4: 0.15 | K4: 36000 | L4: 30600 | M4: 28800 | N4: 1160 | O4: 1585 | P4: =INDEX(Raw_product_master[Standard_Cost_Per_Unit],MATCH(Cleaned_Sales_data[[#This Row],[Product]],Raw_product_master[Product],0)) -> 14400 | Q4: -945 | R4: -0.030882353 | S4: =INDEX(Raw_product_master[Target_Margin], MATCH(Cleaned_Sales_data[[#This Row],[Product]],Raw_product_master[Product], 0 )) -> 0.15 | T4: =IF(Cleaned_Sales_data[[#This Row],[Profit]]>0, "Profitable", "Loss") -> Loss | U4: =_xlfn.IFS(Cleaned_Sales_data[[#This Row],[Profit]]>=10000, "High", Cleaned_Sales_data[[#This Row],[Profit]]>=5000, "Medium", Cleaned_Sales_data[[#This Row],[Profit]]>=0, "Low", Cleaned_Sales_data[[#This Row],[Profit]] <0, "Loss") -> Loss | V4: =IF(R4<S4, "UnderPerforming", "On Target") -> UnderPerforming | W4: 45658
A5: ORD-00015 | B5: 45693 | C5: Headphones | D5: =INDEX(Raw_product_master[Category],MATCH(Cleaned_Sales_data[[#This Row],[Product]],Raw_product_master[Product],0)) -> Accessories | E5: Pune | F5: Online | G5: New | H5: 7 | I5: 3500 | J5: 0.08 | K5: 24500 | L5: 22540 | M5: 16660 | N5: 1394 | O5: 640 | P5: =INDEX(Raw_product_master[Standard_Cost_Per_Unit],MATCH(Cleaned_Sales_data[[#This Row],[Product]],Raw_product_master[Product],0)) -> 2380 | Q5: 3846 | R5: 0.17062999 | S5: =INDEX(Raw_product_master[Target_Margin], MATCH(Cleaned_Sales_data[[#This Row],[Product]],Raw_product_master[Product], 0 )) -> 0.2 | T5: =IF(Cleaned_Sales_data[[#This Row],[Profit]]>0, "Profitable", "Loss") -> Profitable | U5: =_xlfn.IFS(Cleaned_Sales_data[[#This Row],[Profit]]>=10000, "High", Cleaned_Sales_data[[#This Row],[Profit]]>=5000, "Medium", Cleaned_Sales_data[[#This Row],[Profit]]>=0, "Low", Cleaned_Sales_data[[#This Row],[Profit]] <0, "Loss") -> Low | V5: =IF(R5<S5, "UnderPerforming", "On Target") -> UnderPerforming | W5: 45689
A6: ORD-00017 | B6: 45882 | C6: Keyboard | D6: =INDEX(Raw_product_master[Category],MATCH(Cleaned_Sales_data[[#This Row],[Product]],Raw_product_master[Product],0)) -> Accessories | E6: Delhi | F6: Online | G6: New | H6: 2 | I6: 2500 | J6: 0 | K6: 5000 | L6: 5000 | M6: 3100 | N6: 1696 | O6: 2337 | P6: =INDEX(Raw_product_master[Standard_Cost_Per_Unit],MATCH(Cleaned_Sales_data[[#This Row],[Product]],Raw_product_master[Product],0)) -> 1550 | Q6: -2133 | R6: -0.4266 | S6: =INDEX(Raw_product_master[Target_Margin], MATCH(Cleaned_Sales_data[[#This Row],[Product]],Raw_product_master[Product], 0 )) -> 0.25 | T6: =IF(Cleaned_Sales_data[[#This Row],[Profit]]>0, "Profitable", "Loss") -> Loss | U6: =_xlfn.IFS(Cleaned_Sales_data[[#This Row],[Profit]]>=10000, "High", Cleaned_Sales_data[[#This Row],[Profit]]>=5000, "Medium", Cleaned_Sales_data[[#This Row],[Profit]]>=0, "Low", Cleaned_Sales_data[[#This Row],[Profit]] <0, "Loss") -> Loss | V6: =IF(R6<S6, "UnderPerforming", "On Target") -> UnderPerforming | W6: 45870
A7: ORD-00018 | B7: 46113 | C7: Mouse | D7: =INDEX(Raw_product_master[Category],MATCH(Cleaned_Sales_data[[#This Row],[Product]],Raw_product_master[Product],0)) -> Accessories | E7: Bangalore | F7: Online | G7: New | H7: 5 | I7: 1500 | J7: 0.15 | K7: 7500 | L7: 6375 | M7: 4125 | N7: 1582 | O7: 809 | P7: =INDEX(Raw_product_master[Standard_Cost_Per_Unit],MATCH(Cleaned_Sales_data[[#This Row],[Product]],Raw_product_master[Product],0)) -> 825 | Q7: -141 | R7: -0.022117647 | S7: =INDEX(Raw_product_master[Target_Margin], MATCH(Cleaned_Sales_data[[#This Row],[Product]],Raw_product_master[Product], 0 )) -> 0.3 | T7: =IF(Cleaned_Sales_data[[#This Row],[Profit]]>0, "Profitable", "Loss") -> Loss | U7: =_xlfn.IFS(Cleaned_Sales_data[[#This Row],[Profit]]>=10000, "High", Cleaned_Sales_data[[#This Row],[Profit]]>=5000, "Medium", Cleaned_Sales_data[[#This Row],[Profit]]>=0, "Low", Cleaned_Sales_data[[#This Row],[Profit]] <0, "Loss") -> Loss | V7: =IF(R7<S7, "UnderPerforming", "On Target") -> UnderPerforming | W7: 46113
A8: ORD-00019 | B8: 46129 | C8: Keyboard | D8: =INDEX(Raw_product_master[Category],MATCH(Cleaned_Sales_data[[#This Row],[Product]],Raw_product_master[Product],0)) -> Accessories | E8: Delhi | F8: Online | G8: New | H8: 2 | I8: 2500 | J8: 0.05 | K8: 5000 | L8: 4750 | M8: 3100 | N8: 1597 | O8: 1731 | P8: =INDEX(Raw_product_master[Standard_Cost_Per_Unit],MATCH(Cleaned_Sales_data[[#This Row],[Product]],Raw_product_master[Product],0)) -> 1550 | Q8: -1678 | R8: -0.35326316 | S8: =INDEX(Raw_product_master[Target_Margin], MATCH(Cleaned_Sales_data[[#This Row],[Product]],Raw_product_master[Product], 0 )) -> 0.25 | T8: =IF(Cleaned_Sales_data[[#This Row],[Profit]]>0, "Profitable", "Loss") -> Loss | U8: =_xlfn.IFS(Cleaned_Sales_data[[#This Row],[Profit]]>=10000, "High", Cleaned_Sales_data[[#This Row],[Profit]]>=5000, "Medium", Cleaned_Sales_data[[#This Row],[Profit]]>=0, "Low", Cleaned_Sales_data[[#This Row],[Profit]] <0, "Loss") -> Loss | V8: =IF(R8<S8, "UnderPerforming", "On Target") -> UnderPerforming | W8: 46113
A9: ORD-00024 | B9: 46168 | C9: Keyboard | D9: =INDEX(Raw_product_master[Category],MATCH(Cleaned_Sales_data[[#This Row],[Product]],Raw_product_master[Product],0)) -> Accessories | E9: Bangalore | F9: Online | G9: New | H9: 4 | I9: 2500 | J9: 0.05 | K9: 10000 | L9: 9500 | M9: 6200 | N9: 602 | O9: 1469 | P9: =INDEX(Raw_product_master[Standard_Cost_Per_Unit],MATCH(Cleaned_Sales_data[[#This Row],[Product]],Raw_product_master[Product],0)) -> 1550 | Q9: 1229 | R9: 0.12936842 | S9: =INDEX(Raw_product_master[Target_Margin], MATCH(Cleaned_Sales_data[[#This Row],[Product]],Raw_product_master[Product], 0 )) -> 0.25 | T9: =IF(Cleaned_Sales_data[[#This Row],[Profit]]>0, "Profitable", "Loss") -> Profitable | U9: =_xlfn.IFS(Cleaned_Sales_data[[#This Row],[Profit]]>=10000, "High", Cleaned_Sales_data[[#This Row],[Profit]]>=5000, "Medium", Cleaned_Sales_data[[#This Row],[Profit]]>=0, "Low", Cleaned_Sales_data[[#This Row],[Profit]] <0, "Loss") -> Low | V9: =IF(R9<S9, "UnderPerforming", "On Target") -> UnderPerforming | W9: 46143
A10: ORD-00033 | B10: 45829 | C10: Mouse | D10: =INDEX(Raw_product_master[Category],MATCH(Cleaned_Sales_data[[#This Row],[Product]],Raw_product_master[Product],0)) -> Accessories | E10: Hyderabad | F10: Online | G10: New | H10: 3 | I10: 1500 | J10: 0.1 | K10: 4500 | L10: 4050 | M10: 2475 | N10: 1735 | O10: 116 | P10: =INDEX(Raw_product_master[Standard_Cost_Per_Unit],MATCH(Cleaned_Sales_data[[#This Row],[Product]],Raw_product_master[Product],0)) -> 825 | Q10: -276 | R10: -0.068148148 | S10: =INDEX(Raw_product_master[Target_Margin], MATCH(Cleaned_Sales_data[[#This Row],[Product]],Raw_product_master[Product], 0 )) -> 0.3 | T10: =IF(Cleaned_Sales_data[[#This Row],[Profit]]>0, "Profitable", "Loss") -> Loss | U10: =_xlfn.IFS(Cleaned_Sales_data[[#This Row],[Profit]]>=10000, "High", Cleaned_Sales_data[[#This Row],[Profit]]>=5000, "Medium", Cleaned_Sales_data[[#This Row],[Profit]]>=0, "Low", Cleaned_Sales_data[[#This Row],[Profit]] <0, "Loss") -> Loss | V10: =IF(R10<S10, "UnderPerforming", "On Target") -> UnderPerforming | W10: 45809
A11: ORD-00036 | B11: 45945 | C11: Tablet | D11: =INDEX(Raw_product_master[Category],MATCH(Cleaned_Sales_data[[#This Row],[Product]],Raw_product_master[Product],0)) -> Computers | E11: Chennai | F11: Online | G11: New | H11: 2 | I11: 32000 | J11: 0.1 | K11: 64000 | L11: 57600 | M11: 52480 | N11: 885 | O11: 725 | P11: =INDEX(Raw_product_master[Standard_Cost_Per_Unit],MATCH(Cleaned_Sales_data[[#This Row],[Product]],Raw_product_master[Product],0)) -> 26240 | Q11: 3510 | R11: 0.0609375 | S11: =INDEX(Raw_product_master[Target_Margin], MATCH(Cleaned_Sales_data[[#This Row],[Product]],Raw_product_master[Product], 0 )) -> 0.12 | T11: =IF(Cleaned_Sales_data[[#This Row],[Profit]]>0, "Profitable", "Loss") -> Profitable | U11: =_xlfn.IFS(Cleaned_Sales_data[[#This Row],[Profit]]>=10000, "High", Cleaned_Sales_data[[#This Row],[Profit]]>=5000, "Medium", Cleaned_Sales_data[[#This Row],[Profit]]>=0, "Low", Cleaned_Sales_data[[#This Row],[Profit]] <0, "Loss") -> Low | V11: =IF(R11<S11, "UnderPerforming", "On Target") -> UnderPerforming | W11: 45931
A12: ORD-00037 | B12: 45833 | C12: Monitor | D12: =INDEX(Raw_product_master[Category],MATCH(Cleaned_Sales_data[[#This Row],[Product]],Raw_product_master[Product],0)) -> Displays | E12: Pune | F12: Online | G12: New | H12: 2 | I12: 28000 | J12: 0.05 | K12: 56000 | L12: 53200 | M12: 43680 | N12: 1327 | O12: 345 | P12: =INDEX(Raw_product_master[Standard_Cost_Per_Unit],MATCH(Cleaned_Sales_data[[#This Row],[Product]],Raw_product_master[Product],0)) -> 21840 | Q12: 7848 | R12: 0.1475188 | S12: =INDEX(Raw_product_master[Target_Margin], MATCH(Cleaned_Sales_data[[#This Row],[Product]],Raw_product_master[Product], 0 )) -> 0.18 | T12: =IF(Cleaned_Sales_data[[#This Row],[Profit]]>0, "Profitable", "Loss") -> Profitable | U12: =_xlfn.IFS(Cleaned_Sales_data[[#This Row],[Profit]]>=10000, "High", Cleaned_Sales_data[[#This Row],[Profit]]>=5000, "Medium", Cleaned_Sales_data[[#This Row],[Profit]]>=0, "Low", Cleaned_Sales_data[[#This Row],[Profit]] <0, "Loss") -> Medium | V12: =IF(R12<S12, "UnderPerforming", "On Target") -> UnderPerforming | W12: 45809
A13: ORD-00038 | B13: 45693 | C13: Monitor | D13: =INDEX(Raw_product_master[Category],MATCH(Cleaned_Sales_data[[#This Row],[Product]],Raw_product_master[Product],0)) -> Displays | E13: Pune | F13: Online | G13: New | H13: 1 | I13: 28000 | J13: 0.08 | K13: 28000 | L13: 25760 | M13: 21840 | N13: 1027 | O13: 1629 | P13: =INDEX(Raw_product_master[Standard_Cost_Per_Unit],MATCH(Cleaned_Sales_data[[#This Row],[Product]],Raw_product_master[Product],0)) -> 21840 | Q13: 1264 | R13: 0.049068323 | S13: =INDEX(Raw_product_master[Target_Margin], MATCH(Cleaned_Sales_data[[#This Row],[Product]],Raw_product_master[Product], 0 )) -> 0.18 | T13: =IF(Cleaned_Sales_data[[#This Row],[Profit]]>0, "Profitable", "Loss") -> Profitable | U13: =_xlfn.IFS(Cleaned_Sales_data[[#This Row],[Profit]]>=10000, "High", Cleaned_Sales_data[[#This Row],[Profit]]>=5000, "Medium", Cleaned_Sales_data[[#This Row],[Profit]]>=0, "Low", Cleaned_Sales_data[[#This Row],[Profit]] <0, "Loss") -> Low | V13: =IF(R13<S13, "UnderPerforming", "On Target") -> UnderPerforming | W13: 45689
... A751: ORD-00740 | B751: 45714 | C751: Mouse | D751: =INDEX(Raw_product_master[Category],MATCH(Cleaned_Sales_data[[#This Row],[Product]],Raw_product_master[Product],0)) -> Accessories | E751: Pune | F751: Corporate | G751: Returning | H751: 5 | I751: 1500 | J751: 0 | K751: 7500 | L751: 7500 | M751: 4125 | N751: 1753 | O751: 2066 | P751: =INDEX(Raw_product_master[Standard_Cost_Per_Unit],MATCH(Cleaned_Sales_data[[#This Row],[Product]],Raw_product_master[Product],0)) -> 825 | Q751: -444 | R751: -0.0592 | S751: =INDEX(Raw_product_master[Target_Margin], MATCH(Cleaned_Sales_data[[#This Row],[Product]],Raw_product_master[Product], 0 )) -> 0.3 | T751: =IF(Cleaned_Sales_data[[#This Row],[Profit]]>0, "Profitable", "Loss") -> Loss | U751: =_xlfn.IFS(Cleaned_Sales_data[[#This Row],[Profit]]>=10000, "High", Cleaned_Sales_data[[#This Row],[Profit]]>=5000, "Medium", Cleaned_Sales_data[[#This Row],[Profit]]>=0, "Low", Cleaned_Sales_data[[#This Row],[Profit]] <0, "Loss") -> Loss | V751: =IF(R751<S751, "UnderPerforming", "On Target") -> UnderPerforming | W751: 45689

Sheet Raw_Sales_Data
A1: Order_ID | B1: Date | C1: Product | D1: Region | E1: Channel | F1: Customer_Type | G1: Quantity | H1: Unit_Price | I1: Discount | J1: Gross_Sales | K1: Net_Sales | L1: Product_Cost | M1: Shipping_Cost | N1: Marketing_Cost | O1: Profit | P1: Profit_Margin | Q1: Month
A2: ORD-00001 | B2: 45779 | C2: Tablet | D2: Bangalore | E2: Online | F2: Returning | G2: 1 | H2: 32000 | I2: 0.03 | J2: 32000 | K2: 31040 | L2: 26240 | M2: 1295 | N2: 1738 | O2: 1767 | P2: 0.056926546 | Q2: 2025-05
A3: ORD-00002 | B3: 45966 | C3: Headphones | D3: Mumbai | E3: Retail | F3: Enterprise | G3: 4 | H3: 3500 | I3: 0 | J3: 14000 | K3: 14000 | L3: 9520 | M3: 330 | N3: 1785 | O3: 2365 | P3: 0.16892857 | Q3: 2025-11
A4: ORD-00003 | B4: 45910 | C4: Monitor | D4: Hyderabad | E4: Online | F4: Returning | G4: 1 | H4: 28000 | I4: 0.08 | J4: 28000 | K4: 25760 | L4: 21840 | M4: 1537 | N4: 121 | O4: 2262 | P4: 0.087810559 | Q4: 2025-09
A5: ORD-00004 | B5: 45847 | C5: Tablet | D5: Chennai | E5: Retail | F5: New | G5: 2 | H5: 32000 | I5: 0 | J5: 64000 | K5: 64000 | L5: 52480 | M5: 899 | N5: 1075 | O5: 9546 | P5: 0.14915625 | Q5: 2025-07
A6: ORD-00005 | B6: 45824 | C6: Tablet | D6: Mumbai | E6: Corporate | F6: Enterprise | G6: 1 | H6: 32000 | I6: 0 | J6: 32000 | K6: 32000 | L6: 26240 | M6: 846 | N6: 2168 | O6: 2746 | P6: 0.0858125 | Q6: 2025-06
A7: ORD-00006 | B7: 45749 | C7: Monitor | D7: Hyderabad | E7: Online | F7: Returning | G7: 2 | H7: 28000 | I7: 0.05 | J7: 56000 | K7: 53200 | L7: 43680 | M7: 764 | N7: 1463 | O7: 7293 | P7: 0.13708647 | Q7: 2025-04
A8: ORD-00007 | B8: 46047 | C8: Tablet | D8: Chennai | E8: Retail | F8: New | G8: 3 | H8: 32000 | I8: 0.15 | J8: 96000 | K8: 81600 | L8: 78720 | M8: 1785 | N8: 1121 | O8: -26 | P8: -0.00031862745 | Q8: 2026-01
A9: ORD-00008 | B9: 45927 | C9: Tablet | D9: Chennai | E9: Online | F9: New | G9: 2 | H9: 32000 | I9: 0.1 | J9: 64000 | K9: 57600 | L9: 52480 | M9: 361 | N9: 301 | O9: 4458 | P9: 0.077395833 | Q9: 2025-09
A10: ORD-00009 | B10: 45710 | C10: Printer | D10: Mumbai | E10: Corporate | F10: Returning | G10: 1 | H10: 18000 | I10: 0.05 | J10: 18000 | K10: 17100 | L10: 14400 | M10: 537 | N10: 978 | O10: 1185 | P10: 0.069298246 | Q10: 2025-02
A11: ORD-00010 | B11: 45786 | C11: Headphones | D11: Hyderabad | E11: Online | F11: New | G11: 1 | H11: 3500 | I11: 0.05 | J11: 3500 | K11: 3325 | L11: 2380 | M11: 264 | N11: 1467 | O11: -786 | P11: -0.23639098 | Q11: 2025-05
A12: ORD-00011 | B12: 46036 | C12: Keyboard | D12: Pune | E12: Corporate | F12: Returning | G12: 1 | H12: 2500 | I12: 0.1 | J12: 2500 | K12: 2250 | L12: 1550 | M12: 618 | N12: 2436 | O12: -2354 | P12: -1.0462222 | Q12: 2026-01
A13: ORD-00012 | B13: 46064 | C13: Mouse | D13: Chennai | E13: Online | F13: Returning | G13: 7 | H13: 1500 | I13: 0.15 | J13: 10500 | K13: 8925 | L13: 5775 | M13: 979 | N13: 602 | O13: 1569 | P13: 0.17579832 | Q13: 2026-02
... A751: ORD-00750 | B751: 45739 | C751: Printer | D751: Hyderabad | E751: Online | F751: Enterprise | G751: 3 | H751: 18000 | I751: 0.1 | J751: 54000 | K751: 48600 | L751: 43200 | M751: 878 | N751: 2068 | O751: 2454 | P751: 0.050493827 | Q751: 2025-03

Sheet Raw_Product_Master
A1: Product | B1: Category | C1: Standard_Cost_Per_Unit | D1: Target_Margin
A2: Laptop | B2: Computers | C2: 54600 | D2: 0.12
A3: Monitor | B3: Displays | C3: 21840 | D3: 0.18
A4: Keyboard | B4: Accessories | C4: 1550 | D4: 0.25
A5: Mouse | B5: Accessories | C5: 825 | D5: 0.3
A6: Headphones | B6: Accessories | C6: 2380 | D6: 0.2
A7: Webcam | B7: Accessories | C7: 2925 | D7: 0.22
A8: Tablet | B8: Computers | C8: 26240 | D8: 0.12
A9: Printer | B9: Office Equipment | C9: 14400 | D9: 0.15

Sheet Raw_Assumptions
A1: Assumption | B1: Value
A2: Tax_Rate | B2: 0.25
A3: Target_Profit_Margin | B3: 0.2
A4: High_Discount_Threshold | B4: 0.15
